Workbook
Name Slicer_Month: #N/A
Name Slicer_Sector: #N/A
Name Slicer_Year: #N/A

Sheet Raw Data
A1: Sector | B1: Year | C1: Month | D1: Cereals and products | E1: Meat and fish | F1: Egg | G1: Milk and products | H1: Oils and fats | I1: Fruits | J1: Vegetables | K1: Pulses and products | L1: Sugar and Confectionery | M1: Spices | N1: Non-alcoholic beverages | O1: Prepared meals, snacks, sweets etc. | P1: Food and beverages | Q1: Pan, tobacco and intoxicants | R1: Clothing | S1: Footwear | T1: Clothing and footwear | U1: Housing | V1: Fuel and light | W1: Household goods and services | X1: Health | Y1: Transport and communication | Z1: Recreation and amusement | AA1: Education | AB1: Personal care and effects | AC1: Miscellaneous | AD1: General index
A2: Rural | B2: 2013 | C2: January | D2: 107.5 | E2: 106.3 | F2: 108.1 | G2: 104.9 | H2: 106.1 | I2: 103.9 | J2: 101.9 | K2: 106.1 | L2: 106.8 | M2: 103.1 | N2: 104.8 | O2: 106.7 | P2: 105.5 | Q2: 105.1 | R2: 106.5 | S2: 105.8 | T2: 106.4 | U2: NA | V2: 105.5 | W2: 104.8 | X2: 104 | Y2: 103.3 | Z2: 103.4 | AA2: 103.8 | AB2: 104.7 | AC2: 104 | AD2: 105.1
A3: Urban | B3: 2013 | C3: January | D3: 110.5 | E3: 109.1 | F3: 113 | G3: 103.6 | H3: 103.4 | I3: 102.3 | J3: 102.9 | K3: 105.8 | L3: 105.1 | M3: 101.8 | N3: 105.1 | O3: 107.9 | P3: 105.9 | Q3: 105.2 | R3: 105.9 | S3: 105 | T3: 105.8 | U3: 100.3 | V3: 105.4 | W3: 104.8 | X3: 104.1 | Y3: 103.2 | Z3: 102.9 | AA3: 103.5 | AB3: 104.3 | AC3: 103.7 | AD3: 104
A4: Rural+Urban | B4: 2013 | C4: January | D4: 108.4 | E4: 107.3 | F4: 110 | G4: 104.4 | H4: 105.1 | I4: 103.2 | J4: 102.2 | K4: 106 | L4: 106.2 | M4: 102.7 | N4: 104.9 | O4: 107.3 | P4: 105.6 | Q4: 105.1 | R4: 106.3 | S4: 105.5 | T4: 106.2 | U4: 100.3 | V4: 105.5 | W4: 104.8 | X4: 104 | Y4: 103.2 | Z4: 103.1 | AA4: 103.6 | AB4: 104.5 | AC4: 103.9 | AD4: 104.6
A5: Rural | B5: 2013 | C5: February | D5: 109.2 | E5: 108.7 | F5: 110.2 | G5: 105.4 | H5: 106.7 | I5: 104 | J5: 102.4 | K5: 105.9 | L5: 105.7 | M5: 103.1 | N5: 105.1 | O5: 107.7 | P5: 106.3 | Q5: 105.6 | R5: 107.1 | S5: 106.3 | T5: 107 | U5: NA | V5: 106.2 | W5: 105.2 | X5: 104.4 | Y5: 103.9 | Z5: 104 | AA5: 104.1 | AB5: 104.6 | AC5: 104.4 | AD5: 105.8
A6: Urban | B6: 2013 | C6: February | D6: 112.9 | E6: 112.9 | F6: 116.9 | G6: 104 | H6: 103.5 | I6: 103.1 | J6: 104.9 | K6: 104.1 | L6: 103.8 | M6: 102.3 | N6: 106 | O6: 109 | P6: 107.2 | Q6: 106 | R6: 106.6 | S6: 105.5 | T6: 106.4 | U6: 100.4 | V6: 105.7 | W6: 105.2 | X6: 104.7 | Y6: 104.4 | Z6: 103.3 | AA6: 103.7 | AB6: 104.3 | AC6: 104.3 | AD6: 104.7
A7: Rural+Urban | B7: 2013 | C7: February | D7: 110.4 | E7: 110.2 | F7: 112.8 | G7: 104.9 | H7: 105.5 | I7: 103.6 | J7: 103.2 | K7: 105.3 | L7: 105.1 | M7: 102.8 | N7: 105.5 | O7: 108.3 | P7: 106.6 | Q7: 105.7 | R7: 106.9 | S7: 106 | T7: 106.8 | U7: 100.4 | V7: 106 | W7: 105.2 | X7: 104.5 | Y7: 104.2 | Z7: 103.6 | AA7: 103.9 | AB7: 104.5 | AC7: 104.4 | AD7: 105.3
A8: Rural | B8: 2013 | C8: March | D8: 110.2 | E8: 108.8 | F8: 109.9 | G8: 105.6 | H8: 106.2 | I8: 105.7 | J8: 101.4 | K8: 105.7 | L8: 105 | M8: 103.3 | N8: 105.6 | O8: 108.2 | P8: 106.6 | Q8: 106.5 | R8: 107.6 | S8: 106.8 | T8: 107.5 | U8: NA | V8: 106.1 | W8: 105.6 | X8: 104.7 | Y8: 104.6 | Z8: 104 | AA8: 104.3 | AB8: 104.3 | AC8: 104.6 | AD8: 106
A9: Urban | B9: 2013 | C9: March | D9: 113.9 | E9: 111.4 | F9: 113.2 | G9: 104.3 | H9: 102.7 | I9: 104.9 | J9: 103.8 | K9: 103.5 | L9: 102.6 | M9: 102.4 | N9: 107 | O9: 109.8 | P9: 107.3 | Q9: 106.8 | R9: 107.2 | S9: 106 | T9: 107 | U9: 100.4 | V9: 106 | W9: 105.7 | X9: 105.2 | Y9: 105.5 | Z9: 103.5 | AA9: 103.8 | AB9: 104.2 | AC9: 104.9 | AD9: 105
A10: Rural+Urban | B10: 2013 | C10: March | D10: 111.4 | E10: 109.7 | F10: 111.2 | G10: 105.1 | H10: 104.9 | I10: 105.3 | J10: 102.2 | K10: 105 | L10: 104.2 | M10: 103 | N10: 106.2 | O10: 108.9 | P10: 106.9 | Q10: 106.6 | R10: 107.4 | S10: 106.5 | T10: 107.3 | U10: 100.4 | V10: 106.1 | W10: 105.6 | X10: 104.9 | Y10: 105.1 | Z10: 103.7 | AA10: 104 | AB10: 104.3 | AC10: 104.7 | AD10: 105.5
A11: Rural | B11: 2013 | C11: April | D11: 110.2 | E11: 109.5 | F11: 106.9 | G11: 106.3 | H11: 105.7 | I11: 108.3 | J11: 103.4 | K11: 105.7 | L11: 104.2 | M11: 103.2 | N11: 106.5 | O11: 108.8 | P11: 107.1 | Q11: 107.1 | R11: 108.1 | S11: 107.4 | T11: 108 | U11: NA | V11: 106.5 | W11: 106.1 | X11: 105.1 | Y11: 104.4 | Z11: 104.5 | AA11: 104.8 | AB11: 102.7 | AC11: 104.6 | AD11: 106.4
A12: Urban | B12: 2013 | C12: April | D12: 114.6 | E12: 113.4 | F12: 106 | G12: 104.7 | H12: 102.1 | I12: 109.5 | J12: 109.7 | K12: 104.6 | L12: 102 | M12: 103.5 | N12: 108.2 | O12: 110.6 | P12: 108.8 | Q12: 108.5 | R12: 107.9 | S12: 106.4 | T12: 107.7 | U12: 100.5 | V12: 106.4 | W12: 106.5 | X12: 105.7 | Y12: 105 | Z12: 104 | AA12: 105.2 | AB12: 103.2 | AC12: 105.1 | AD12: 105.7
A13: Rural+Urban | B13: 2013 | C13: April | D13: 111.6 | E13: 110.9 | F13: 106.6 | G13: 105.7 | H13: 104.4 | I13: 108.9 | J13: 105.5 | K13: 105.3 | L13: 103.5 | M13: 103.3 | N13: 107.2 | O13: 109.6 | P13: 107.7 | Q13: 107.5 | R13: 108 | S13: 107 | T13: 107.9 | U13: 100.5 | V13: 106.5 | W13: 106.3 | X13: 105.3 | Y13: 104.7 | Z13: 104.2 | AA13: 105 | AB13: 102.9 | AC13: 104.8 | AD13: 106.1
A14: Rural | B14: 2013 | C14: May | D14: 110.9 | E14: 109.8 | F14: 105.9 | G14: 107.5 | H14: 105.3 | I14: 108.1 | J14: 107.3 | K14: 106.1 | L14: 103.7 | M14: 104 | N14: 107.4 | O14: 109.9 | P14: 108.1 | Q14: 108.1 | R14: 108.8 | S14: 107.9 | T14: 108.6 | U14: NA | V14: 107.5 | W14: 106.8 | X14: 105.7 | Y14: 104.1 | Z14: 105 | AA14: 105.5 | AB14: 102.1 | AC14: 104.8 | AD14: 107.2
A15: Urban | B15: 2013 | C15: May | D15: 115.4 | E15: 114.2 | F15: 102.7 | G15: 105.5 | H15: 101.5 | I15: 110.6 | J15: 123.7 | K15: 105.2 | L15: 101.9 | M15: 105 | N15: 109.1 | O15: 111.3 | P15: 111.1 | Q15: 109.8 | R15: 108.5 | S15: 106.7 | T15: 108.3 | U15: 100.5 | V15: 107.2 | W15: 107.1 | X15: 106.2 | Y15: 103.9 | Z15: 104.6 | AA15: 105.7 | AB15: 102.6 | AC15: 104.9 | AD15: 106.6
A16: Rural+Urban | B16: 2013 | C16: May | D16: 112.3 | E16: 111.3 | F16: 104.7 | G16: 106.8 | H16: 103.9 | I16: 109.3 | J16: 112.9 | K16: 105.8 | L16: 103.1 | M16: 104.3 | N16: 108.1 | O16: 110.5 | P16: 109.2 | Q16: 108.6 | R16: 108.7 | S16: 107.4 | T16: 108.5 | U16: 100.5 | V16: 107.4 | W16: 106.9 | X16: 105.9 | Y16: 104 | Z16: 104.8 | AA16: 105.6 | AB16: 102.3 | AC16: 104.8 | AD16: 106.9
A17: Rural | B17: 2013 | C17: June | D17: 112.3 | E17: 112.1 | F17: 108.1 | G17: 108.3 | H17: 105.9 | I17: 109.2 | J17: 118 | K17: 106.8 | L17: 104.1 | M17: 105.4 | N17: 108.2 | O17: 111 | P17: 110.6 | Q17: 109 | R17: 109.7 | S17: 108.8 | T17: 109.5 | U17: NA | V17: 108.5 | W17: 107.5 | X17: 106.3 | Y17: 105 | Z17: 105.6 | AA17: 106.5 | AB17: 102.5 | AC17: 105.5 | AD17: 108.9
A18: Urban | B18: 2013 | C18: June | D18: 117 | E18: 120.1 | F18: 112.5 | G18: 107.3 | H18: 101.3 | I18: 112.4 | J18: 143.6 | K18: 105.4 | L18: 101.4 | M18: 106.4 | N18: 110 | O18: 112.2 | P18: 115 | Q18: 110.9 | R18: 109.2 | S18: 107.2 | T18: 108.9 | U18: 106.6 | V18: 108 | W18: 107.7 | X18: 106.5 | Y18: 105.2 | Z18: 105.2 | AA18: 108.1 | AB18: 103.3 | AC18: 106.1 | AD18: 109.7
A19: Rural+Urban | B19: 2013 | C19: June | D19: 113.8 | E19: 114.9 | F19: 109.8 | G19: 107.9 | H19: 104.2 | I19: 110.7 | J19: 126.7 | K19: 106.3 | L19: 103.2 | M19: 105.7 | N19: 109 | O19: 111.6 | P19: 112.2 | Q19: 109.5 | R19: 109.5 | S19: 108.1 | T19: 109.3 | U19: 106.6 | V19: 108.3 | W19: 107.6 | X19: 106.4 | Y19: 105.1 | Z19: 105.4 | AA19: 107.4 | AB19: 102.8 | AC19: 105.8 | AD19: 109.3
A20: Rural | B20: 2013 | C20: July | D20: 113.4 | E20: 114.9 | F20: 110.5 | G20: 109.3 | H20: 106.2 | I20: 110.3 | J20: 129.2 | K20: 107.1 | L20: 104.3 | M20: 106.4 | N20: 109.1 | O20: 112.1 | P20: 113.1 | Q20: 109.8 | R20: 110.5 | S20: 109.5 | T20: 110.3 | U20: NA | V20: 109.5 | W20: 108.3 | X20: 106.9 | Y20: 106.8 | Z20: 106.4 | AA20: 107.8 | AB20: 102.5 | AC20: 106.5 | AD20: 110.7
A21: Urban | B21: 2013 | C21: July | D21: 117.8 | E21: 119.2 | F21: 114 | G21: 108.3 | H21: 101.1 | I21: 113.2 | J21: 160.9 | K21: 105.1 | L21: 101.3 | M21: 107.5 | N21: 110.4 | O21: 113.1 | P21: 117.5 | Q21: 111.7 | R21: 109.8 | S21: 107.8 | T21: 109.5 | U21: 107.7 | V21: 108.6 | W21: 108.1 | X21: 107.1 | Y21: 107.3 | Z21: 105.9 | AA21: 110.1 | AB21: 103.2 | AC21: 107.3 | AD21: 111.4
A22: Rural+Urban | B22: 2013 | C22: July | D22: 114.8 | E22: 116.4 | F22: 111.9 | G22: 108.9 | H22: 104.3 | I22: 111.7 | J22: 140 | K22: 106.4 | L22: 103.3 | M22: 106.8 | N22: 109.6 | O22: 112.6 | P22: 114.7 | Q22: 110.3 | R22: 110.2 | S22: 108.8 | T22: 110 | U22: 107.7 | V22: 109.2 | W22: 108.2 | X22: 107 | Y22: 107.1 | Z22: 106.1 | AA22: 109.1 | AB22: 102.8 | AC22: 106.9 | AD22: 111
A23: Rural | B23: 2013 | C23: August | D23: 114.3 | E23: 115.4 | F23: 111.1 | G23: 110 | H23: 106.4 | I23: 110.8 | J23: 138.9 | K23: 107.4 | L23: 104.1 | M23: 106.9 | N23: 109.7 | O23: 112.6 | P23: 114.9 | Q23: 110.7 | R23: 111.3 | S23: 110.2 | T23: 111.1 | U23: NA | V23: 109.9 | W23: 108.7 | X23: 107.5 | Y23: 107.8 | Z23: 106.8 | AA23: 108.7 | AB23: 105 | AC23: 107.5 | AD23: 112.1
A24: Urban | B24: 2013 | C24: August | D24: 118.3 | E24: 120.4 | F24: 112.7 | G24: 108.9 | H24: 101.1 | I24: 108.7 | J24: 177 | K24: 104.7 | L24: 101 | M24: 108.5 | N24: 110.9 | O24: 114.3 | P24: 119.6 | Q24: 112.4 | R24: 110.6 | S24: 108.3 | T24: 110.2 | U24: 108.9 | V24: 109.3 | W24: 108.7 | X24: 107.6 | Y24: 108.1 | Z24: 106.5 | AA24: 110.8 | AB24: 106 | AC24: 108.3 | AD24: 112.7
A25: Rural+Urban | B25: 2013 | C25: August | D25: 115.6 | E25: 117.2 | F25: 111.7 | G25: 109.6 | H25: 104.5 | I25: 109.8 | J25: 151.8 | K25: 106.5 | L25: 103.1 | M25: 107.4 | N25: 110.2 | O25: 113.4 | P25: 116.6 | Q25: 111.2 | R25: 111 | S25: 109.4 | T25: 110.7 | U25: 108.9 | V25: 109.7 | W25: 108.7 | X25: 107.5 | Y25: 108 | Z25: 106.6 | AA25: 109.9 | AB25: 105.4 | AC25: 107.9 | AD25: 112.4
A26: Rural | B26: 2013 | C26: September | D26: 115.4 | E26: 115.7 | F26: 111.7 | G26: 111 | H26: 107.4 | I26: 110.9 | J26: 154 | K26: 108.1 | L26: 104.2 | M26: 107.9 | N26: 110.4 | O26: 114 | P26: 117.8 | Q26: 111.7 | R26: 112.7 | S26: 111.4 | T26: 112.5 | U26: NA | V26: 111.1 | W26: 109.6 | X26: 108.3 | Y26: 109.3 | Z26: 107.7 | AA26: 109.8 | AB26: 106.7 | AC26: 108.7 | AD26: 114.2
A27: Urban | B27: 2013 | C27: September | D27: 118.6 | E27: 119.1 | F27: 113.2 | G27: 109.6 | H27: 101.7 | I27: 103.2 | J27: 174.3 | K27: 105.1 | L27: 100.8 | M27: 109.1 | N27: 111.1 | O27: 115.4 | P27: 119.2 | Q27: 112.9 | R27: 111.4 | S27: 109 | T27: 111.1 | U27: 109.7 | V27: 109.5 | W27: 109.6 | X27: 107.9 | Y27: 110.4 | Z27: 107.4 | AA27: 111.2 | AB27: 106.9 | AC27: 109.4 | AD27: 113.2
A28: Rural+Urban | B28: 2013 | C28: September | D28: 116.4 | E28: 116.9 | F28: 112.3 | G28: 110.5 | H28: 105.3 | I28: 107.3 | J28: 160.9 | K28: 107.1 | L28: 103.1 | M28: 108.3 | N28: 110.7 | O28: 114.6 | P28: 118.3 | Q28: 112 | R28: 112.2 | S28: 110.4 | T28: 111.9 | U28: 109.7 | V28: 110.5 | W28: 109.6 | X28: 108.1 | Y28: 109.9 | Z28: 107.5 | AA28: 110.6 | AB28: 106.8 | AC28: 109 | AD28: 113.7
A29: Rural | B29: 2013 | C29: October | D29: 116.3 | E29: 115.4 | F29: 112.6 | G29: 111.7 | H29: 107.7 | I29: 113.2 | J29: 164.9 | K29: 108.3 | L29: 103.9 | M29: 108.2 | N29: 111.1 | O29: 114.9 | P29: 119.8 | Q29: 112.2 | R29: 113.6 | S29: 112.3 | T29: 113.4 | U29: NA | V29: 111.6 | W29: 110.4 | X29: 108.9 | Y29: 109.3 | Z29: 108.3 | AA29: 110.2 | AB29: 107.5 | AC29: 109.1 | AD29: 115.5
A30: Urban | B30: 2013 | C30: October | D30: 118.9 | E30: 118.1 | F30: 114.5 | G30: 110.4 | H30: 102.3 | I30: 106.2 | J30: 183.5 | K30: 105.3 | L30: 100.2 | M30: 109.6 | N30: 111.4 | O30: 116 | P30: 120.8 | Q30: 113.5 | R30: 112.5 | S30: 109.7 | T30: 112 | U30: 110.5 | V30: 109.7 | W30: 110.2 | X30: 108.2 | Y30: 109.7 | Z30: 108 | AA30: 111.3 | AB30: 107.3 | AC30: 109.4 | AD30: 114
A31: Rural+Urban | B31: 2013 | C31: October | D31: 117.1 | E31: 116.3 | F31: 113.3 | G31: 111.2 | H31: 105.7 | I31: 109.9 | J31: 171.2 | K31: 107.3 | L31: 102.7 | M31: 108.7 | N31: 111.2 | O31: 115.4 | P31: 120.2 | Q31: 112.5 | R31: 113.2 | S31: 111.2 | T31: 112.8 | U31: 110.5 | V31: 110.9 | W31: 110.3 | X31: 108.6 | Y31: 109.5 | Z31: 108.1 | AA31: 110.8 | AB31: 107.4 | AC31: 109.2 | AD31: 114.8
A32: Rural | B32: 2013 | C32: November | D32: 117.3 | E32: 114.9 | F32: 116.2 | G32: 112.8 | H32: 108.9 | I32: 116.6 | J32: 178.1 | K32: 109.1 | L32: 103.6 | M32: 109 | N32: 111.8 | O32: 116 | P32: 122.5 | Q32: 112.8 | R32: 114.6 | S32: 113.1 | T32: 114.4 | U32: NA | V32: 112.6 | W32: 111.3 | X32: 109.7 | Y32: 109.6 | Z32: 108.7 | AA32: 111 | AB32: 108.2 | AC32: 109.8 | AD32: 117.4
A33: Urban | B33: 2013 | C33: November | D33: 119.8 | E33: 116.3 | F33: 122.6 | G33: 112 | H33: 103.2 | I33: 110 | J33: 192.8 | K33: 106.3 | L33: 99.5 | M33: 110.3 | N33: 111.8 | O33: 117.1 | P33: 122.9 | Q33: 114.1 | R33: 113.5 | S33: 110.3 | T33: 113 | U33: 111.1 | V33: 110 | W33: 110.9 | X33: 108.6 | Y33: 109.5 | Z33: 108.5 | AA33: 111.3 | AB33: 107.9 | AC33: 109.6 | AD33: 115
A34: Rural+Urban | B34: 2013 | C34: November | D34: 118.1 | E34: 115.4 | F34: 118.7 | G34: 112.5 | H34: 106.8 | I34: 113.5 | J34: 183.1 | K34: 108.2 | L34: 102.2 | M34: 109.4 | N34: 111.8 | O34: 116.5 | P34: 122.6 | Q34: 113.1 | R34: 114.2 | S34: 111.9 | T34: 113.8 | U34: 111.1 | V34: 111.6 | W34: 111.1 | X34: 109.3 | Y34: 109.5 | Z34: 108.6 | AA34: 111.2 | AB34: 108.1 | AC34: 109.7 | AD34: 116.3
A35: Rural | B35: 2013 | C35: December | D35: 118.4 | E35: 115.9 | F35: 120.4 | G35: 113.8 | H35: 109.5 | I35: 115.5 | J35: 145.7 | K35: 109.5 | L35: 102.9 | M35: 109.8 | N35: 112.1 | O35: 116.8 | P35: 118.7 | Q35: 113.6 | R35: 115.8 | S35: 114 | T35: 115.5 | U35: NA | V35: 112.8 | W35: 112.1 | X35: 110.1 | Y35: 109.9 | Z35: 109.2 | AA35: 111.6 | AB35: 108.1 | AC35: 110.1 | AD35: 115.5
A36: Urban | B36: 2013 | C36: December | D36: 120.5 | E36: 118.1 | F36: 128.5 | G36: 112.8 | H36: 103.4 | I36: 110.7 | J36: 144.8 | K36: 107.1 | L36: 98.6 | M36: 111.9 | N36: 112.1 | O36: 118.1 | P36: 117.8 | Q36: 115 | R36: 114.2 | S36: 110.9 | T36: 113.7 | U36: 110.7 | V36: 110.4 | W36: 111.3 | X36: 109 | Y36: 109.7 | Z36: 108.9 | AA36: 111.4 | AB36: 107.7 | AC36: 109.8 | AD36: 113.3
A37: Rural+Urban | B37: 2013 | C37: December | D37: 119.1 | E37: 116.7 | F37: 123.5 | G37: 113.4 | H37: 107.3 | I37: 113.3 | J37: 145.4 | K37: 108.7 | L37: 101.5 | M37: 110.5 | N37: 112.1 | O37: 117.4 | P37: 118.4 | Q37: 114 | R37: 115.2 | S37: 112.7 | T37: 114.8 | U37: 110.7 | V37: 111.9 | W37: 111.7 | X37: 109.7 | Y37: 109.8 | Z37: 109 | AA37: 111.5 | AB37: 107.9 | AC37: 110 | AD37: 114.5
A38: Rural | B38: 2014 | C38: January | D38: 118.9 | E38: 117.1 | F38: 120.5 | G38: 114.4 | H38: 109 | I38: 115.5 | J38: 123.9 | K38: 109.6 | L38: 101.8 | M38: 110.2 | N38: 112.4 | O38: 117.3 | P38: 116 | Q38: 114 | R38: 116.5 | S38: 114.5 | T38: 116.2 | U38: NA | V38: 113 | W38: 112.6 | X38: 110.6 | Y38: 110.5 | Z38: 109.6 | AA38: 111.8 | AB38: 108.3 | AC38: 110.6 | AD38: 114.2
A39: Urban | B39: 2014 | C39: January | D39: 121.2 | E39: 122 | F39: 129.9 | G39: 113.6 | H39: 102.9 | I39: 112.1 | J39: 118.9 | K39: 107.5 | L39: 96.9 | M39: 112.7 | N39: 112.1 | O39: 119 | P39: 115.5 | Q39: 115.7 | R39: 114.8 | S39: 111.3 | T39: 114.3 | U39: 111.6 | V39: 111 | W39: 111.9 | X39: 109.7 | Y39: 110.8 | Z39: 109.8 | AA39: 111.5 | AB39: 108 | AC39: 110.5 | AD39: 112.9
A40: Rural+Urban | B40: 2014 | C40: January | D40: 119.6 | E40: 118.8 | F40: 124.1 | G40: 114.1 | H40: 106.8 | I40: 113.9 | J40: 122.2 | K40: 108.9 | L40: 100.2 | M40: 111 | N40: 112.3 | O40: 118.1 | P40: 115.8 | Q40: 114.5 | R40: 115.8 | S40: 113.2 | T40: 115.4 | U40: 111.6 | V40: 112.2 | W40: 112.3 | X40: 110.3 | Y40: 110.7 | Z40: 109.7 | AA40: 111.6 | AB40: 108.2 | AC40: 110.6 | AD40: 113.6
...

Sheet Data Dictionary
C1: Data Dictionary | F1: Broad categories
C2: Column Name | D2: Description | F2: FOOD & BEVERAGES
C3: Sector | D3: Sector where the consumer lives | F3: Cereals and products
C4: Year | D4: Year in which the products are consumed | F4: Meat and fish
C5: Month | D5: Month in which the products are consumed | F5: Egg
C6: Cereals and products | D6: Index value paid by the consumers for cereals and products | F6: Milk and products
C7: Meat and fish | D7: Index value paid by the consumers for meat and fish | F7: Oils and fats
C8: Egg | D8: Index value paid by the consumers on egg | F8: Fruits
C9: Milk and products | D9: Index value paid by the consumers for milk and products | F9: Vegetables
C10: Oils and fats | D10: Index value paid by the consumers for oil and fats | F10: Pulses and products
C11: Fruits | D11: Index value paid by the consumers for fruits | F11: Sugar and Confectionery
C12: Vegetables | D12: Index value paid by the consumers for vegetable | F12: Spices
C13: Pulses and products | D13: Index value paid by the consumers for pulses and products | F13: Non-alcoholic beverages
... C15: Spices | D15: Index value paid by the consumers for non alcoholic beverages | F15: Food and beverages
C16: Non-alcoholic beverages | D16: Index value paid by the consumers for meat and fish
C17: Prepared meals, snacks, sweets etc. | D17: Index value paid by the consumers on prepared meals,snacks,sweets,etc | F17: INTOXICANTS & TOBACCO
C18: Food and beverages | D18: Index value paid by the consumers for food and biverages | F18: Pan, tobacco and intoxicants
C19: Pan, tobacco and intoxicants | D19: Index value paid by the consumers Pan, tobacco and intoxicants products
C20: Clothing | D20: Index value spent by the consumers on clothing | F20: CLOTHING AND FOOTWEAR
C21: Footwear | D21: Index value spent by the consumers on footwear | F21: Clothing
C22: Clothing and footwear | D22: Index value spent by the consumers on clothing and footwear | F22: Footwear
C23: Housing | D23: Index value spent by the consumers on housing | F23: Clothing and footwear
C24: Fuel and light | D24: Index value spent by the consumers on fuel and light
C25: Household goods and services | D25: Index value spent by the consumers on household goods and services | F25: HOUSING
C26: Health | D26: Index value spent by the consumers on their health | F26: Housing
C27: Transport and communication | D27: Index value spent by the consumers on their transport and communication | F27: Fuel and light
C28: Recreation and amusement | D28: Index value spent by the consumers for their recreation and amusement | F28: Household goods and services
C29: Education | D29: Index value spent by the consumers on their education
C30: Personal care and effects | D30: Index value spent by the consumers on their personal care and effects | F30: MISCELLANEOUS
C31: Miscellaneous | D31: Index value spent on miscellaneous things | F31: Health
C32: General Index | D32: Overall index value for all the categories combined of the month | F32: Education
F33: Transport and communication
F34: Recreation and amusement
F35: Personal care and effects
F36: Miscellaneous

Sheet Main Data
A1: Sector | B1: Year | C1: Month | D1: YearMonth | E1: Cereals and products | F1: Meat and fish | G1: Egg | H1: Milk and products | I1: Oils and fats | J1: Fruits | K1: Vegetables | L1: Pulses and products | M1: Sugar and Confectionery | N1: Spices | O1: Non-alcoholic beverages | P1: Prepared meals, snacks, sweets etc. | Q1: Food and beverages | R1: Pan, tobacco and intoxicants | S1: Clothing | T1: Footwear | U1: Clothing and footwear | V1: Housing | W1: Fuel and light | X1: Household goods and services | Y1: Health | Z1: Transport and communication | AA1: Recreation and amusement | AB1: Education | AC1: Personal care and effects | AD1: Miscellaneous | AE1: General index
A2: Urban | B2: 2022 | C2: July | D2: July 2022 | E2: 159.3 | F2: 217.1 | G2: 176.6 | H2: 167.1 | I2: 184.8 | J2: 179.5 | K2: 208.5 | L2: 164 | M2: 121.5 | N2: 186.3 | O2: 159.8 | P2: 187.7 | Q2: 179.4 | R2: 198.6 | S2: 172.7 | T2: 158.7 | U2: 170.6 | V2: 167.8 | W2: 179.5 | X2: 163.1 | Y2: 171.7 | Z2: 157.4 | AA2: 164.6 | AB2: 169.1 | AC2: 169.8 | AD2: 164.7 | AE2: 172.3
A3: Urban | B3: 2023 | C3: April | D3: April 2023 | E3: 174.8 | F3: 213.7 | G3: 172.4 | H3: 178.8 | I3: 168.7 | J3: 179.2 | K3: 179.9 | L3: 174.7 | M3: 123.1 | N3: 207.8 | O3: 165.5 | P3: 197 | Q3: 182.1 | R3: 203.5 | S3: 181 | T3: 167.7 | U3: 178.9 | V3: 175.2 | W3: 182.1 | X3: 169.6 | Y3: 181.5 | Z3: 160.1 | AA3: 168.8 | AB3: 174.2 | AC3: 184.4 | AD3: 170.9 | AE3: 177.4
A4: Urban | B4: 2022 | C4: August | D4: August 2022 | E4: 162.1 | F4: 210.9 | G4: 170.6 | H4: 168.4 | I4: 182.5 | J4: 177.1 | K4: 213.1 | L4: 167.3 | M4: 122.2 | N4: 189.7 | O4: 160.5 | P4: 188.9 | Q4: 180.4 | R4: 198.7 | S4: 173.7 | T4: 160 | U4: 171.6 | V4: 169 | W4: 178.4 | X4: 164.2 | Y4: 172.6 | Z4: 157.7 | AA4: 165.1 | AB4: 169.9 | AC4: 171.4 | AD4: 165.4 | AE4: 173.1
A5: Rural+Urban | B5: 2023 | C5: April | D5: April 2023 | E5: 173.8 | F5: 209.3 | G5: 169.6 | H5: 178.4 | I5: 174.9 | J5: 176.3 | K5: 155.4 | L5: 173.4 | M5: 121.3 | N5: 212.9 | O5: 172.9 | P5: 193.5 | Q5: 177.9 | R5: 200.6 | S5: 186.9 | T5: 179.2 | U5: 185.7 | V5: 175.2 | W5: 181.7 | X5: 174.6 | Y5: 185 | Z5: 164.5 | AA5: 170.7 | AB5: 176.4 | AC5: 184 | AD5: 175 | AE5: 178.1
A6: Urban | B6: 2022 | C6: April | D6: April 2022 | E6: 155.4 | F6: 215.8 | G6: 164.6 | H6: 164.2 | I6: 186 | J6: 175.9 | K6: 190.7 | L6: 164 | M6: 120.5 | N6: 178 | O6: 157.5 | P6: 183.3 | Q6: 174.5 | R6: 197.1 | S6: 168.4 | T6: 154.5 | U6: 166.3 | V6: 167 | W6: 170.5 | X6: 159.8 | Y6: 169 | Z6: 159.3 | AA6: 162.2 | AB6: 164 | AC6: 168.4 | AD6: 163.1 | AE6: 169.2
A7: Urban | B7: 2023 | C7: May | D7: May 2023 | E7: 174.7 | F7: 219.4 | G7: 176.7 | H7: 179.4 | I7: 164.4 | J7: 175.8 | K7: 185 | L7: 176.9 | M7: 124.2 | N7: 211.9 | O7: 165.9 | P7: 197.7 | Q7: 183.1 | R7: 204.2 | S7: 181.3 | T7: 168.1 | U7: 179.3 | V7: 175.6 | W7: 183.4 | X7: 170.1 | Y7: 182.2 | Z7: 160.4 | AA7: 169.2 | AB7: 174.8 | AC7: 185.6 | AD7: 171.6 | AE7: 178.2
A8: Urban | B8: 2022 | C8: May | D8: May 2022 | E8: 156.7 | F8: 221.2 | G8: 164.1 | H8: 165.4 | I8: 189.5 | J8: 174.5 | K8: 203.2 | L8: 164.1 | M8: 121.2 | N8: 181.4 | O8: 158.5 | P8: 184.9 | Q8: 177.5 | R8: 197.5 | S8: 170 | T8: 155.9 | U8: 167.8 | V8: 167.5 | W8: 173.5 | X8: 161.1 | Y8: 170.1 | Z8: 159.4 | AA8: 163.2 | AB8: 165.2 | AC8: 168.2 | AD8: 163.8 | AE8: 170.8
A9: Rural+Urban | B9: 2022 | C9: July | D9: July 2022 | E9: 156.5 | F9: 213 | G9: 175.2 | H9: 166.6 | I9: 195.8 | J9: 174.2 | K9: 182.1 | L9: 164.3 | M9: 120 | N9: 190 | O9: 168.4 | P9: 185.2 | Q9: 175 | R9: 194.6 | S9: 178.3 | T9: 171.3 | U9: 177.3 | V9: 167.8 | W9: 179.6 | X9: 167.4 | Y9: 176.1 | Z9: 161.6 | AA9: 166.3 | AB9: 171.4 | AC9: 169.7 | AD9: 168.4 | AE9: 173.4
A10: Urban | B10: 2022 | C10: June | D10: June 2022 | E10: 157.5 | F10: 223.4 | G10: 172.8 | H10: 166.4 | I10: 188.6 | J10: 174.1 | K10: 211.5 | L10: 163.6 | M10: 121.4 | N10: 183.5 | O10: 159.1 | P10: 186.3 | Q10: 179.3 | R10: 198.3 | S10: 171.6 | T10: 157.4 | U10: 169.4 | V10: 166.8 | W10: 174.9 | X10: 162.1 | Y10: 170.9 | Z10: 157.2 | AA10: 164.1 | AB10: 166.5 | AC10: 169.2 | AD10: 163.8 | AE10: 171.4
A11: Rural | B11: 2023 | C11: April | D11: April 2023 | E11: 173.3 | F11: 206.9 | G11: 167.9 | H11: 178.2 | I11: 178.5 | J11: 173.7 | K11: 142.8 | L11: 172.8 | M11: 120.4 | N11: 215.5 | O11: 178.2 | P11: 190.5 | Q11: 175.5 | R11: 199.5 | S11: 190.7 | T11: 187.3 | U11: 190.2 | V11: 175.2 | W11: 181.5 | X11: 179.1 | Y11: 187.2 | Z11: 169.4 | AA11: 173.2 | AB11: 179.4 | AC11: 183.8 | AD11: 178.9 | AE11: 178.8
A12: Rural+Urban | B12: 2022 | C12: August | D12: August 2022 | E12: 160.3 | F12: 206.5 | G12: 169.2 | H12: 168.1 | I12: 192.4 | J12: 172.9 | K12: 186.7 | L12: 167.2 | M12: 120.9 | N12: 193.6 | O12: 168.8 | P12: 186.3 | Q12: 176.3 | R12: 195 | S12: 179.5 | T12: 172.7 | U12: 178.5 | V12: 169 | W12: 178.8 | X12: 168.5 | Y12: 176.8 | Z12: 161.9 | AA12: 166.9 | AB12: 172.3 | AC12: 171.2 | AD12: 169.1 | AE12: 174.3
A13: Rural+Urban | B13: 2022 | C13: April | D13: April 2022 | E13: 152.9 | F13: 211.8 | G13: 164.5 | H13: 163.9 | I13: 199.5 | J13: 172.6 | K13: 166.2 | L13: 164.7 | M13: 119 | N13: 181.3 | O13: 166.2 | P13: 180.9 | Q13: 170.8 | R13: 193.9 | S13: 173.9 | T13: 166.5 | U13: 172.8 | V13: 167 | W13: 172.2 | X13: 164 | Y13: 174 | Z13: 162.6 | AA13: 164.4 | AB13: 166.9 | AC13: 168.8 | AD13: 166.8 | AE13: 170.1
... A20: Urban | B20: 2021 | C20: July | D20: July 2021 | E20: 149.1 | F20: 210.9 | G20: 185 | H20: 158.2 | I20: 170.6 | J20: 170.9 | K20: 186.4 | L20: 164.7 | M20: 115.7 | N20: 165.5 | O20: 153.4 | P20: 173.5 | Q20: 167.9 | R20: 195.5 | S20: 157.9 | T20: 141.9 | U20: 155.5 | V20: 161.5 | W20: 157.7 | X20: 150.7 | Y20: 161.5 | Z20: 149.5 | AA20: 151.2 | AB20: 160.3 | AC20: 159.6 | AD20: 155 | AE20: 161.8
A21: Rural | B21: 2022 | C21: April | D21: April 2022 | E21: 151.8 | F21: 209.7 | G21: 164.5 | H21: 163.8 | I21: 207.4 | J21: 169.7 | K21: 153.6 | L21: 165.1 | M21: 118.2 | N21: 182.9 | O21: 172.4 | P21: 178.9 | Q21: 168.6 | R21: 192.8 | S21: 177.5 | T21: 175.1 | U21: 177.1 | V21: =VLOOKUP($D21,Notes!$B$2:$C$229,2,0) -> 167 | W21: 173.3 | X21: 167.7 | Y21: 177 | Z21: 166.2 | AA21: 167.2 | AB21: 170.9 | AC21: 169 | AD21: 170.2 | AE21: 170.8
A22: Rural+Urban | B22: 2022 | C22: June | D22: June 2022 | E22: 155 | F22: 219.4 | G22: 170.8 | H22: 165.8 | I22: 200.9 | J22: 169.7 | K22: 182.3 | L22: 164.3 | M22: 119.9 | N22: 187.1 | O22: 167.9 | P22: 183.9 | Q22: 174.9 | R22: 194.3 | S22: 177.1 | T22: 169.9 | U22: 176 | V22: 166.8 | W22: 176 | X22: 166.4 | Y22: 175.4 | Z22: 161.1 | AA22: 165.8 | AB22: 169 | AC22: 169.4 | AD22: 167.5 | AE22: 172.6
A23: Rural | B23: 2022 | C23: July | D23: July 2022 | E23: 155.2 | F23: 210.8 | G23: 174.3 | H23: 166.3 | I23: 202.2 | J23: 169.6 | K23: 168.6 | L23: 164.4 | M23: 119.2 | N23: 191.8 | O23: 174.5 | P23: 183.1 | Q23: 172.5 | R23: 193.2 | S23: 182 | T23: 180.3 | U23: 181.7 | V23: =VLOOKUP($D23,Notes!$B$2:$C$229,2,0) -> 167.8 | W23: 179.6 | X23: 171.3 | Y23: 178.8 | Z23: 166.3 | AA23: 168.6 | AB23: 174.7 | AC23: 169.7 | AD23: 171.8 | AE23: 174.3
A24: Rural+Urban | B24: 2023 | C24: February | D24: February 2023 | E24: 174.4 | F24: 207.7 | G24: 175.2 | H24: 177.3 | I24: 179.3 | J24: 169.5 | K24: 152.7 | L24: 171 | M24: 120 | N24: 209.7 | O24: 172.3 | P24: 193 | Q24: 177 | R24: 199.5 | S24: 186.2 | T24: 178.7 | U24: 185.1 | V24: 173.5 | W24: 182.1 | X24: 174.2 | Y24: 184.4 | Z24: 164.2 | AA24: 170.3 | AB24: 175 | AC24: 181 | AD24: 174.1 | AE24: 177.2
A25: Rural+Urban | B25: 2023 | C25: March | D25: March 2023 | E25: 174.4 | F25: 207.7 | G25: 175.2 | H25: 177.3 | I25: 179.2 | J25: 169.5 | K25: 152.8 | L25: 171.1 | M25: 120 | N25: 209.7 | O25: 172.3 | P25: 193 | Q25: 177 | R25: 199.5 | S25: 186.1 | T25: 178.7 | U25: 185.1 | V25: 173.5 | W25: 181.9 | X25: 174.2 | Y25: 184.4 | Z25: 164.2 | AA25: 170.3 | AB25: 175 | AC25: 181 | AD25: 174.1 | AE25: 177.2
A26: Rural | B26: 2022 | C26: August | D26: August 2022 | E26: 159.5 | F26: 204.1 | G26: 168.3 | H26: 167.9 | I26: 198.1 | J26: 169.2 | K26: 173.1 | L26: 167.1 | M26: 120.2 | N26: 195.6 | O26: 174.8 | P26: 184 | Q26: 173.9 | R26: 193.7 | S26: 183.2 | T26: 181.7 | U26: 183 | V26: =VLOOKUP($D26,Notes!$B$2:$C$229,2,0) -> 169 | W26: 179.1 | X26: 172.3 | Y26: 179.4 | Z26: 166.6 | AA26: 169.3 | AB26: 175.7 | AC26: 171.1 | AD26: 172.6 | AE26: 175.3
A27: Rural | B27: 2023 | C27: May | D27: May 2023 | E27: 173.2 | F27: 211.5 | G27: 171 | H27: 179.6 | I27: 173.3 | J27: 169 | K27: 148.7 | L27: 174.9 | M27: 121.9 | N27: 221 | O27: 178.7 | P27: 191.1 | Q27: 176.8 | R27: 199.9 | S27: 191.2 | T27: 187.9 | U27: 190.8 | V27: 175.6 | W27: 182.5 | X27: 179.8 | Y27: 187.8 | Z27: 169.7 | AA27: 173.8 | AB27: 180.3 | AC27: 184.9 | AD27: 179.5 | AE27: 179.8
A28: Urban | B28: 2021 | C28: April | D28: April 2021 | E28: 147.6 | F28: 202.5 | G28: 166.4 | H28: 156 | I28: 161.4 | J28: 168.8 | K28: 161.6 | L28: 162.8 | M28: 114.8 | N28: 162.8 | O28: 151.5 | P28: 171.4 | Q28: 162 | R28: 194.4 | S28: 155.9 | T28: 139.3 | U28: 153.4 | V28: 161.4 | W28: 154.9 | X28: 147.6 | Y28: 157.5 | Z28: 142.1 | AA28: 149.1 | AB28: 157.6 | AC28: 156.6 | AD28: 150.5 | AE28: 158
A29: Rural | B29: 2022 | C29: May | D29: May 2022 | E29: 152.9 | F29: 214.7 | G29: 161.4 | H29: 164.6 | I29: 209.9 | J29: 168 | K29: 160.4 | L29: 165 | M29: 118.9 | N29: 186.6 | O29: 173.2 | P29: 180.4 | Q29: 170.8 | R29: 192.9 | S29: 179.3 | T29: 177.2 | U29: 179 | V29: =VLOOKUP($D29,Notes!$B$2:$C$229,2,0) -> 167.5 | W29: 175.3 | X29: 168.9 | Y29: 177.7 | Z29: 167.1 | AA29: 167.6 | AB29: 171.8 | AC29: 168.5 | AD29: 170.9 | AE29: 172.5
A30: Urban | B30: 2022 | C30: September | D30: September 2022 | E30: 164.9 | F30: 213.7 | G30: 170.9 | H30: 170.1 | I30: 179.3 | J30: 167.5 | K30: 220.8 | L30: 169.2 | M30: 123.1 | N30: 193.6 | O30: 161.1 | P30: 190.4 | Q30: 181.8 | R30: 199.7 | S30: 175 | T30: 161.7 | U30: 173 | V30: 169.5 | W30: 179.2 | X30: 165 | Y30: 173.8 | Z30: 158.2 | AA30: 165.8 | AB30: 170.9 | AC30: 171.1 | AD30: 166.1 | AE30: 174.1
A31: Rural | B31: 2023 | C31: February | D31: February 2023 | E31: 174.2 | F31: 205.2 | G31: 173.9 | H31: 177 | I31: 183.4 | J31: 167.2 | K31: 140.9 | L31: 170.4 | M31: 119.1 | N31: 212.1 | O31: 177.6 | P31: 189.9 | Q31: 174.8 | R31: 198.3 | S31: 190 | T31: 187 | U31: 189.6 | V31: =VLOOKUP($D31,Notes!$B$2:$C$229,2,0) -> 173.5 | W31: 181.6 | X31: 178.6 | Y31: 186.6 | Z31: 169 | AA31: 172.8 | AB31: 178.5 | AC31: 180.7 | AD31: 177.9 | AE31: 178
A32: Rural | B32: 2023 | C32: March | D32: March 2023 | E32: 174.3 | F32: 205.2 | G32: 173.9 | H32: 177 | I32: 183.3 | J32: 167.2 | K32: 140.9 | L32: 170.5 | M32: 119.1 | N32: 212.1 | O32: 177.6 | P32: 189.9 | Q32: 174.8 | R32: 198.4 | S32: 190 | T32: 187 | U32: 189.6 | V32: =VLOOKUP($D32,Notes!$B$2:$C$229,2,0) -> 173.5 | W32: 181.4 | X32: 178.6 | Y32: 186.6 | Z32: 169 | AA32: 172.8 | AB32: 178.5 | AC32: 180.7 | AD32: 177.9 | AE32: 178
A33: Rural+Urban | B33: 2021 | C33: May | D33: May 2021 | E33: 146.3 | F33: 200.5 | G33: 170.3 | H33: 156.1 | I33: 178.7 | J33: 167.1 | K33: 147.9 | L33: 165.4 | M33: 114.8 | N33: 168.2 | O33: 159.3 | P33: 170.4 | Q33: 160.7 | R33: 191.9 | S33: 161.8 | T33: 152.1 | U33: 160.4 | V33: 161.6 | W33: 159.4 | X33: 154.7 | Y33: 165.8 | Z33: 148.9 | AA33: 155.8 | AB33: 161.2 | AC33: 158.6 | AD33: 156.8 | AE33: 160.4
A34: Rural | B34: 2022 | C34: June | D34: June 2022 | E34: 153.8 | F34: 217.2 | G34: 169.6 | H34: 165.4 | I34: 208.1 | J34: 165.8 | K34: 167.3 | L34: 164.6 | M34: 119.1 | N34: 188.9 | O34: 174.2 | P34: 181.9 | Q34: 172.4 | R34: 192.9 | S34: 180.7 | T34: 178.7 | U34: 180.4 | V34: =VLOOKUP($D34,Notes!$B$2:$C$229,2,0) -> 166.8 | W34: 176.7 | X34: 170.3 | Y34: 178.2 | Z34: 165.5 | AA34: 168 | AB34: 172.6 | AC34: 169.5 | AD34: 171 | AE34: 173.6
A35: Rural+Urban | B35: 2022 | C35: September | D35: September 2022 | E35: 163.5 | F35: 209.2 | G35: 169.7 | H35: 169.7 | I35: 188.7 | J35: 165.7 | K35: 191.8 | L35: 169.1 | M35: 121.6 | N35: 197.3 | O35: 169.4 | P35: 187.4 | Q35: 177.8 | R35: 195.9 | S35: 180.9 | T35: 174.3 | U35: 179.9 | V35: 169.5 | W35: 179.5 | X35: 169.5 | Y35: 177.8 | Z35: 162.3 | AA35: 167.6 | AB35: 173.1 | AC35: 170.9 | AD35: 169.7 | AE35: 175.3
A36: Urban | B36: 2022 | C36: October | D36: October 2022 | E36: 166.4 | F36: 214.9 | G36: 171.9 | H36: 171 | I36: 177.7 | J36: 165.7 | K36: 228.6 | L36: 169.9 | M36: 123.4 | N36: 196.4 | O36: 161.6 | P36: 191.5 | Q36: 183.3 | R36: 200.1 | S36: 175.5 | T36: 162.6 | U36: 173.6 | V36: 171.2 | W36: 180 | X36: 166 | Y36: 174.7 | Z36: 158.8 | AA36: 166.3 | AB36: 171.2 | AC36: 172.3 | AD36: 166.8 | AE36: 175.3
A37: Rural+Urban | B37: 2021 | C37: June | D37: June 2021 | E37: 146.7 | F37: 202 | G37: 180.7 | H37: 156.2 | I37: 183.7 | J37: 164.6 | K37: 155.4 | L37: 166 | M37: 115.1 | N37: 168.5 | O37: 160 | P37: 172.4 | Q37: 162.6 | R37: 190.8 | S37: 162.2 | T37: 151.8 | U37: 160.7 | V37: 160.5 | W37: 159.8 | X37: 154.8 | Y37: 166.3 | Z37: 150.7 | AA37: 154.9 | AB37: 161.7 | AC37: 158.8 | AD37: 157.6 | AE37: 161.3
A38: Rural+Urban | B38: 2021 | C38: April | D38: April 2021 | E38: 144.3 | F38: 198 | G38: 164.6 | H38: 155.4 | I38: 170.1 | J38: 164.4 | K38: 144.1 | L38: 161.7 | M38: 113.1 | N38: 163.9 | O38: 157.6 | P38: 168.9 | Q38: 158 | R38: 188.8 | S38: 158.8 | T38: 148.5 | U38: 157.3 | V38: 161.4 | W38: 155.6 | X38: 151.8 | Y38: 162.3 | Z38: 146.6 | AA38: 153.2 | AB38: 160.3 | AC38: 155.4 | AD38: 154.4 | AE38: 157.8
A39: Rural | B39: 2022 | C39: September | D39: September 2022 | E39: 162.9 | F39: 206.7 | G39: 169 | H39: 169.5 | I39: 194.1 | J39: 164.1 | K39: 176.9 | L39: 169 | M39: 120.8 | N39: 199.1 | O39: 175.4 | P39: 184.8 | Q39: 175.5 | R39: 194.5 | S39: 184.7 | T39: 183.3 | U39: 184.5 | V39: =VLOOKUP($D39,Notes!$B$2:$C$229,2,0) -> 169.5 | W39: 179.7 | X39: 173.6 | Y39: 180.2 | Z39: 166.9 | AA39: 170 | AB39: 176.2 | AC39: 170.8 | AD39: 173.1 | AE39: 176.4
A40: Rural+Urban | B40: 2021 | C40: July | D40: July 2021 | E40: 146.4 | F40: 206.8 | G40: 182.2 | H40: 157.5 | I40: 182.1 | J40: 163.9 | K40: 164.2 | L40: 164 | M40: 114.5 | N40: 168.3 | O40: 160.9 | P40: 172.2 | Q40: 164 | R40: 191.2 | S40: 162.8 | T40: 153.1 | U40: 161.4 | V40: 161.5 | W40: 160.7 | X40: 155.8 | Y40: 167 | Z40: 153.1 | AA40: 155.3 | AB40: 163.2 | AC40: 160.1 | AD40: 159 | AE40: 162.5
A41: Rural+Urban | B41: 2022 | C41: October | D41: October 2022 | E41: 165.2 | F41: 210.9 | G41: 170.9 | H41: 170.9 | I41: 186.5 | J41: 163.8 | K41: 199.7 | L41: 169.8 | M41: 121.9 | N41: 199.9 | O41: 169.9 | P41: 188.3 | Q41: 179.6 | R41: 196.3 | S41: 181.9 | T41: 175.3 | U41: 181 | V41: 171.2 | W41: 180.5 | X41: 170.4 | Y41: 178.7 | Z41: 162.9 | AA41: 168.2 | AB41: 173.4 | AC41: 172.1 | AD41: 170.5 | AE41: 176.7
A42: Urban | B42: 2022 | C42: November | D42: November 2022 | E42: 168.4 | F42: 213.4 | G42: 183.2 | H42: 172.3 | I42: 180 | J42: 162.6 | K42: 205.5 | L42: 171 | M42: 123.4 | N42: 198.8 | O42: 162.1 | P42: 192.4 | Q42: 181.3 | R42: 200.6 | S42: 176.7 | T42: 163.5 | U42: 174.7 | V42: 171.8 | W42: 180.3 | X42: 166.9 | Y42: 175.8 | Z42: 158.9 | AA42: 166.7 | AB42: 171.5 | AC42: 173.8 | AD42: 167.4 | AE42: 174.1
A43: Rural | B43: 2021 | C43: May | D43: May 2021 | E43: 145.1 | F43: 198.5 | G43: 168.6 | H43: 155.8 | I43: 184.4 | J43: 162.3 | K43: 138.4 | L43: 165.1 | M43: 114.3 | N43: 169.7 | O43: 164.6 | P43: 169.8 | Q43: 158.7 | R43: 189.6 | S43: 165.3 | T43: 160.6 | U43: 164.5 | V43: =VLOOKUP($D43,Notes!$B$2:$C$229,2,0) -> 161.6 | W43: 161.7 | X43: 158.8 | Y43: 169.1 | Z43: 153.2 | AA43: 160 | AB43: 167.6 | AC43: 159.3 | AD43: 161.1 | AE43: 161.1
A44: Rural | B44: 2022 | C44: October | D44: October 2022 | E44: 164.7 | F44: 208.8 | G44: 170.3 | H44: 170.9 | I44: 191.6 | J44: 162.2 | K44: 184.8 | L44: 169.7 | M44: 121.1 | N44: 201.6 | O44: 175.8 | P44: 185.6 | Q44: 177.4 | R44: 194.9 | S44: 186.1 | T44: 184.4 | U44: 185.9 | V44: =VLOOKUP($D44,Notes!$B$2:$C$229,2,0) -> 171.2 | W44: 180.8 | X44: 174.4 | Y44: 181.2 | Z44: 167.4 | AA44: 170.6 | AB44: 176.5 | AC44: 172 | AD44: 173.9 | AE44: 177.9
A45: Urban | B45: 2021 | C45: August | D45: August 2021 | E45: 149.3 | F45: 207.4 | G45: 174.1 | H45: 159.2 | I45: 175 | J45: 161.3 | K45: 183.3 | L45: 164.5 | M45: 120.4 | N45: 166.2 | O45: 154.8 | P45: 175.1 | Q45: 167.3 | R45: 196.5 | S45: 159.8 | T45: 143.6 | U45: 157.3 | V45: 162.1 | W45: 160.7 | X45: 153.2 | Y45: 162.8 | Z45: 150.4 | AA45: 153.7 | AB45: 160.4 | AC45: 159.6 | AD45: 156 | AE45: 162.3
A46: Urban | B46: 2021 | C46: September | D46: September 2021 | E46: 149.3 | F46: 207.4 | G46: 174.1 | H46: 159.1 | I46: 175 | J46: 161.2 | K46: 183.5 | L46: 164.5 | M46: 120.4 | N46: 166.2 | O46: 154.8 | P46: 175.1 | Q46: 167.3 | R46: 196.5 | S46: 159.8 | T46: 143.6 | U46: 157.4 | V46: 162.1 | W46: 160.8 | X46: 153.3 | Y46: 162.8 | Z46: 150.5 | AA46: 153.9 | AB46: 160.3 | AC46: 159.6 | AD46: 156 | AE46: 162.3
...

Sheet Broad Categories
A1: Sector | B1: YearMonth | C1: Year | D1: Month | E1: Food and beverages | F1: Pan, tobacco and intoxicants | G1: Clothing and footwear | H1: Housing | I1: Miscellaneous | J1: General index
A2: Rural | B2: January 2013 | C2: 2013 | D2: January | E2: 1371.7 | F2: 105.1 | G2: 318.7 | H2: 310.6 | I2: 831 | J2: 105.1
A3: Urban | B3: January 2013 | C3: 2013 | D3: January | E3: 1376.4 | F3: 105.2 | G3: 316.7 | H3: 310.5 | I3: 829.3 | J3: 104
A4: Rural+Urban | B4: January 2013 | C4: 2013 | D4: January | E4: 1373.3 | F4: 105.1 | G4: 318 | H4: 310.6 | I4: 829.9 | J4: 104.6
A5: Rural | B5: February 2013 | C5: 2013 | D5: February | E5: 1380.4 | F5: 105.6 | G5: 320.4 | H5: 311.8 | I5: 833.9 | J5: 105.8
A6: Urban | B6: February 2013 | C6: 2013 | D6: February | E6: 1390.6 | F6: 106 | G6: 318.5 | H6: 311.3 | I6: 833.1 | J6: 104.7
A7: Rural+Urban | B7: February 2013 | C7: 2013 | D7: February | E7: 1384.2 | F7: 105.7 | G7: 319.7 | H7: 311.6 | I7: 833.5 | J7: 105.3
A8: Rural | B8: March 2013 | C8: 2013 | D8: March | E8: 1382.2 | F8: 106.5 | G8: 321.9 | H8: 312.1 | I8: 835.5 | J8: 106
A9: Urban | B9: March 2013 | C9: 2013 | D9: March | E9: 1386.8 | F9: 106.8 | G9: 320.2 | H9: 312.1 | I9: 836.1 | J9: 105
A10: Rural+Urban | B10: March 2013 | C10: 2013 | D10: March | E10: 1384 | F10: 106.6 | G10: 321.2 | H10: 312.1 | I10: 835.6 | J10: 105.5
A11: Rural | B11: April 2013 | C11: 2013 | D11: April | E11: 1385.8 | F11: 107.1 | G11: 323.5 | H11: 313.1 | I11: 836 | J11: 106.4
A12: Urban | B12: April 2013 | C12: 2013 | D12: April | E12: 1397.7 | F12: 108.5 | G12: 322 | H12: 313.4 | I12: 839.1 | J12: 105.7
A13: Rural+Urban | B13: April 2013 | C13: 2013 | D13: April | E13: 1390.2 | F13: 107.5 | G13: 322.9 | H13: 313.3 | I13: 837.2 | J13: 106.1
... A373: Rural+Urban | B373: May 2023 | C373: 2023 | D373: May | E373: 2306.9 | F373: 201 | G373: 553.2 | H373: 533.6 | I373: 1422.5 | J373: 179.1

Sheet EDA 1
B1: OBJECTIVE 1 | C1: identify which broad category in the CPI basket contributes the most to overall inflation for the latest month (May 2023).
B4: Sector | C4: YearMonth | D4: Food and beverages | E4: Pan, tobacco and intoxicants | F4: Clothing and footwear | G4: Housing | H4: Miscellaneous | I4: General index
B5: Rural | C5: May 2023 | D5: 2290.7 | E5: 199.9 | F5: 569.9 | G5: 537.9 | H5: 1444.1 | I5: 179.8
B6: Urban | C6: May 2023 | D6: 2335.1 | E6: 204.2 | F6: 528.7 | G6: 529.1 | H6: 1400.8 | I6: 178.2
B7: Rural+Urban | C7: May 2023 | D7: 2306.9 | E7: 201 | F7: 553.2 | G7: 533.6 | H7: 1422.5 | I7: 179.1
B10: CONTRIBUTION OF RURAL+URBAN IN MAY 2023
B11: Broad Categories | C11: Total index value | D11: % of contribution
B12: Food and beverages | C12: =AVERAGEIFS($D$7:$I$7,$D$4:$I$4,$B12) -> 2306.9 | D12: =C12/$C$17*100 -> 45.979829
B13: Pan, tobacco and intoxicants | C13: =AVERAGEIFS($D$7:$I$7,$D$4:$I$4,$B13) -> 201 | D13: =C13/$C$17*100 -> 4.0062186
B14: Clothing and footwear | C14: =AVERAGEIFS($D$7:$I$7,$D$4:$I$4,$B14) -> 553.2 | D14: =C14/$C$17*100 -> 11.02607
B15: Housing | C15: =AVERAGEIFS($D$7:$I$7,$D$4:$I$4,$B15) -> 533.6 | D15: =C15/$C$17*100 -> 10.635414
B16: Miscellaneous | C16: =AVERAGEIFS($D$7:$I$7,$D$4:$I$4,$B16) -> 1422.5 | D16: =C16/$C$17*100 -> 28.352468
B17: Total | C17: =SUM(C12:C16) -> 5017.2 | D17: =C17/C17*100 -> 100
E32: INSIGHTS
E33: 1.Food and beverages is the biggest contributor among all the other categories by contributing 42% more than the least contributed category.
E34: 2.Housing and clothing contributed equally during May 2023 which tells us that consumers spent equally on their lifestyle.
E35: 3.Tobacco and intoxicants contributed the least as not all the consumers consumes it but all the other category is consumed by all the consumers somehow.

Sheet EDA 2
B1: OBJECTIVE 2 | E1: To analyze the year-on-year (Y-o-Y) trend of CPI inflation (combining rural and urban data) from 2017 onwards.
B4: Rural+Urban General index | G4: Y-O-Y INFLATION
B5: Sector | C5: Year | D5: Month | E5: General index | G5: Year | H5: January | I5: December | J5: Inflation
B6: Rural+Urban | C6: 2013 | D6: January | E6: 104.6 | G6: 2017 | H6: =AVERAGEIFS($E$6:$E$129,$C$6:$C$129,$G6,$D$6:$D$129,H$5) -> 130.3 | I6: =AVERAGEIFS($E$6:$E$129,$C$6:$C$129,$G6,$D$6:$D$129,I$5) -> 137.2 | J6: =($I6-$H6)/$H6 -> 0.05295472
B7: Rural+Urban | C7: 2013 | D7: February | E7: 105.3 | G7: =G6+1 -> 2018 | H7: =AVERAGEIFS($E$6:$E$129,$C$6:$C$129,$G7,$D$6:$D$129,H$5) -> 136.9 | I7: =AVERAGEIFS($E$6:$E$129,$C$6:$C$129,$G7,$D$6:$D$129,I$5) -> 140.1 | J7: =($I7-$H7)/$H7 -> 0.023374726
B8: Rural+Urban | C8: 2013 | D8: March | E8: 105.5 | G8: =G7+1 -> 2019 | H8: =AVERAGEIFS($E$6:$E$129,$C$6:$C$129,$G8,$D$6:$D$129,H$5) -> 139.6 | I8: =AVERAGEIFS($E$6:$E$129,$C$6:$C$129,$G8,$D$6:$D$129,I$5) -> 150.4 | J8: =($I8-$H8)/$H8 -> 0.077363897
B9: Rural+Urban | C9: 2013 | D9: April | E9: 106.1 | G9: =G8+1 -> 2020 | H9: =AVERAGEIFS($E$6:$E$129,$C$6:$C$129,$G9,$D$6:$D$129,H$5) -> 150.2 | I9: =AVERAGEIFS($E$6:$E$129,$C$6:$C$129,$G9,$D$6:$D$129,I$5) -> 158.9 | J9: =($I9-$H9)/$H9 -> 0.05792277
B10: Rural+Urban | C10: 2013 | D10: May | E10: 106.9 | G10: =G9+1 -> 2021 | H10: =AVERAGEIFS($E$6:$E$129,$C$6:$C$129,$G10,$D$6:$D$129,H$5) -> 157.3 | I10: =AVERAGEIFS($E$6:$E$129,$C$6:$C$129,$G10,$D$6:$D$129,I$5) -> 166.2 | J10: =($I10-$H10)/$H10 -> 0.056579784
B11: Rural+Urban | C11: 2013 | D11: June | E11: 109.3 | G11: =G10+1 -> 2022 | H11: =AVERAGEIFS($E$6:$E$129,$C$6:$C$129,$G11,$D$6:$D$129,H$5) -> 165.7 | I11: =AVERAGEIFS($E$6:$E$129,$C$6:$C$129,$G11,$D$6:$D$129,I$5) -> 175.7 | J11: =($I11-$H11)/$H11 -> 0.06035003
B12: Rural+Urban | C12: 2013 | D12: July | E12: 111 | G12: =G11+1 -> 2023 | H12: =AVERAGEIFS($E$6:$E$129,$C$6:$C$129,$G12,$D$6:$D$129,H$5) -> 176.5 | J12: cant be calculated as we are not having the value of december 2023.
B13: Rural+Urban | C13: 2013 | D13: August | E13: 112.4
B14: Rural+Urban | C14: 2013 | D14: September | E14: 113.7
B15: Rural+Urban | C15: 2013 | D15: October | E15: 114.8
B16: Rural+Urban | C16: 2013 | D16: November | E16: 116.3
B17: Rural+Urban | C17: 2013 | D17: December | E17: 114.5
B18: Rural+Urban | C18: 2014 | D18: January | E18: 113.6
B19: Rural+Urban | C19: 2014 | D19: February | E19: 113.6
B20: Rural+Urban | C20: 2014 | D20: March | E20: 114.2
B21: Rural+Urban | C21: 2014 | D21: April | E21: 115.1
B22: Rural+Urban | C22: 2014 | D22: May | E22: 115.8
B23: Rural+Urban | C23: 2014 | D23: June | E23: 116.7
B24: Rural+Urban | C24: 2014 | D24: July | E24: 119.2
... B35: Rural+Urban | C35: 2015 | D35: June | E35: 123
B36: Rural+Urban | C36: 2015 | D36: July | E36: 123.6 | I36: INSIGHTS
B37: Rural+Urban | C37: 2015 | D37: August | E37: 124.8 | I37: Reasons for 2019 being the highest
B38: Rural+Urban | C38: 2015 | D38: September | E38: 125.4 | I38: 1.Due to floods in major producing states, the prices of fruits,vegetables and various goods increases.
B39: Rural+Urban | C39: 2015 | D39: October | E39: 126.1 | I39: 2.The main reason of this being the highest is just because of food inflation which accounted over 70% in the inflation rate.
B40: Rural+Urban | C40: 2015 | D40: November | E40: 126.6 | I40: 3.Another reason is increase in the prices of the crude oil.
B41: Rural+Urban | C41: 2015 | D41: December | E41: 126.1
B42: Rural+Urban | C42: 2016 | D42: January | E42: 126.3
B43: Rural+Urban | C43: 2016 | D43: February | E43: 126
B44: Rural+Urban | C44: 2016 | D44: March | E44: 126
B45: Rural+Urban | C45: 2016 | D45: April | E45: 127.3
B46: Rural+Urban | C46: 2016 | D46: May | E46: 128.6
B47: Rural+Urban | C47: 2016 | D47: June | E47: 130.1
B48: Rural+Urban | C48: 2016 | D48: July | E48: 131.1
B49: Rural+Urban | C49: 2016 | D49: August | E49: 131.1
B50: Rural+Urban | C50: 2016 | D50: September | E50: 130.9
B51: Rural+Urban | C51: 2016 | D51: October | E51: 131.4
B52: Rural+Urban | C52: 2016 | D52: November | E52: 131.2
...

Sheet EDA 3
B1: OBJECTIVE 3 | D1: To analyze monthly trends(Highest and Lowest Month) and key contributors to food inflation in India for the month of June 2022 till May 2023.
B4: YearMonth | C4: Food and beverages | D4: M-O-M Inflation
B5: May 2022 | C5: 2238.9
B6: June 2022 | C6: 2261.9 | D6: =($C6-$C5)/$C5*100 -> 1.0272902
B7: July 2022 | C7: 2266.3 | D7: =($C7-$C6)/$C6*100 -> 0.19452673
B8: August 2022 | C8: 2269.2 | D8: =($C8-$C7)/$C7*100 -> 0.12796188
B9: September 2022 | C9: 2280.9 | D9: =($C9-$C8)/$C8*100 -> 0.51560021
B10: October 2022 | C10: 2297.3 | D10: =($C10-$C9)/$C9*100 -> 0.71901442
B11: November 2022 | C11: 2296.8 | D11: =($C11-$C10)/$C10*100 -> -0.02176468 | O11: INSIGHTS
B12: December 2022 | C12: 2283.4 | D12: =($C12-$C11)/$C11*100 -> -0.58342041 | O12: Prepared meals, snacks, sweets etc. had contributed the most in the food and beverages category
B13: January 2023 | C13: 2292.7 | D13: =($C13-$C12)/$C12*100 -> 0.40728738 | O13: June 2022 has the largest M-O-M inflation by having 1.027%
B14: February 2023 | C14: 2279.1 | D14: =($C14-$C13)/$C13*100 -> -0.59318707 | O14: February 2023 is having the least M-O-M by having -0.583
B15: March 2023 | C15: 2279.2 | D15: =($C15-$C14)/$C14*100 -> 0.0043876969
B16: April 2023 | C16: 2289.6 | D16: =($C16-$C15)/$C15*100 -> 0.45630046
B17: May 2023 | C17: 2306.9 | D17: =($C17-$C16)/$C16*100 -> 0.7555905
C26: Cereals and products | D26: Meat and fish | E26: Egg | F26: Milk and products | G26: Oils and fats | H26: Fruits | I26: Vegetables | J26: Pulses and products | K26: Sugar and Confectionery | L26: Spices | M26: Non-alcoholic beverages | N26: Prepared meals, snacks, sweets etc. | O26: Food and beverages
B27: SUM | C27: 12.08522 | D27: -1.0960038 | E27: 7.5858021 | F27: 8.5207275 | G27: -11.618753 | H27: 5.9318799 | I27: 6.5629058 | J27: 15.169684 | K27: 3.3958434 | L27: 6.6560215 | M27: 2.8797011 | N27: 42.753076 | O27: -1490.3233
B32: Year | C32: Month | D32: Cereals and products | E32: Meat and fish | F32: Egg | G32: Milk and products | H32: Oils and fats | I32: Fruits | J32: Vegetables | K32: Pulses and products | L32: Sugar and Confectionery | M32: Spices | N32: Non-alcoholic beverages | O32: Prepared meals, snacks, sweets etc. | P32: Food and beverages
B33: 2022 | C33: June | D33: 0.58403634 | E33: 1.1059908 | F33: 5.1724138 | G33: 0.54578532 | H33: -0.74110672 | I33: -0.76023392 | J33: 4.2309891 | K33: -0.24286582 | L33: 0.16708438 | M33: 1.1898323 | N33: 0.47875524 | O33: 0.76712329 | P33: 0.92325447
B34: 2022 | C34: July | D34: 0.96774194 | E34: -2.9170465 | F34: 2.5761124 | G34: 0.48250905 | H34: -0.10970927 | I34: 0 | J34: 0.083402836 | K34: 1.5499733 | L34: 0.29779631 | M34: 0.70690593 | N34: 0.057175529 | O34: 65.698925 | P34: -363.74962
B35: 2022 | C35: August | D35: 2.428115 | E35: -3.0516432 | F35: -3.4246575 | G35: 0.90036014 | H35: 2.5260846 | I35: 1.7650639 | J35: 0.75 | K35: 1.8947368 | L35: 0.23752969 | M35: 0.59395248 | N35: 0.74285714 | O35: 150.90522 | P35: 4.6141432
B36: 2022 | C36: September | D36: 1.996257 | E36: 1.3075061 | F36: 0.29550827 | G36: 0.9518144 | H36: 2.7316551 | I36: 1.1363636 | J36: 0.5789909 | K36: 1.911157 | L36: 0.35545024 | M36: 0.59044552 | N36: 0.85082246 | O36: -17.785731 | P36: -142.84597
B37: 2022 | C37: October | D37: 1.0397554 | E37: 0.8126195 | F37: 0.70713023 | G37: 0.70713023 | H37: 4.1188738 | I37: 0.41395624 | J37: 0.24671053 | K37: 1.3177902 | L37: 0.29515939 | M37: 0.48025614 | N37: 1.0123735 | O37: -47.914755 | P37: -37.849657
B38: 2022 | C38: November | D38: 1.3317191 | E38: -0.71123755 | F38: 6.1439438 | G38: 0.81919251 | H38: -8.3124687 | I38: 0.41224971 | J38: 0.16406891 | K38: 1.4507254 | L38: 0.29429076 | M38: 0.63728093 | N38: -0.72383073 | O38: 28.080046 | P38: -187.52406
B39: 2022 | C39: December | D39: 1.0752688 | E39: -0.19102197 | F39: 4.8511577 | G39: 0.75449797 | H39: -12.670672 | I39: 0.17595308 | J39: -0.24570025 | K39: 1.183432 | L39: 0.35211268 | M39: 0.42216359 | N39: -1.346046 | O39: -19.257087 | P39: -73.142311
B40: 2023 | C40: January | D40: 2.7186761 | E40: 0.81339713 | F40: 2.2607781 | G40: 0.57603687 | H40: -3.7523452 | I40: 0.058548009 | J40: -0.57471264 | K40: 1.5594542 | L40: 0.23391813 | M40: 0.47293747 | N40: 0.45480387 | O40: 152.83688 | P40: -525.8134
B41: 2023 | C41: February | D41: 0.3452244 | E41: -1.4238253 | F41: -9.9228792 | G41: 1.5463918 | H41: -0.7797271 | I41: 0.058513751 | J41: -0.90834021 | K41: 0.62380038 | L41: 0.52508751 | M41: 0.94142259 | N41: 0.16977929 | O41: -87.301746 | P41: -275.04676
B42: 2023 | C42: March | D42: 0 | E42: 0 | F42: 0 | G42: 0 | H42: 0.065487885 | I42: 0.058479532 | J42: 0 | K42: 0 | L42: 0 | M42: 0 | N42: 0 | O42: -100 | P42: -100
B43: 2023 | C43: April | D43: -0.3440367 | E43: 0.77034184 | F43: -3.196347 | G43: 0.62041737 | H43: 1.7015707 | I43: 1.3442431 | J43: 1.0833333 | K43: 1.5259895 | L43: 0.34822983 | M43: 0.25906736 | N43: 0.50847458
B44: 2023 | C44: May | D44: -0.057537399 | E44: 2.3889154 | F44: 2.1226415 | G44: 0.61659193 | H44: 3.6036036 | I44: 1.2687428 | J44: 1.1541632 | K44: 2.3954908 | L44: 0.2891845 | M44: 0.36175711 | N44: 0.67453626 | O44: -83.275796 | P44: 210.11108
C46: SUM | D46: =SUM(D33:D44) -> 12.08522 | E46: =SUM(E33:E44) -> -1.0960038 | F46: =SUM(F33:F44) -> 7.5858021 | G46: =SUM(G33:G44) -> 8.5207275 | H46: =SUM(H33:H44) -> -11.618753 | I46: =SUM(I33:I44) -> 5.9318799 | J46: =SUM(J33:J44) -> 6.5629058 | K46: =SUM(K33:K44) -> 15.169684 | ... P46: =SUM(P33:P44) -> -1490.3233
D51: FORMULA USED
D52: (current_month-previous_month)/previous_month*100

Sheet EDA 4
B1: OBJECTIVE 4 | E1: to examine how COVID-19 affected inflation in India, especially in essential services,healthcare and food, by comparing CPI trends before and after March 2020 and explaining the reasons for any major changes.
B4: PROBLEM 4 | C4: 24 months before march 2020 | H4: 24 months before march 2020
B5: Year | C5: Month | D5: INFLATION(FOOD) | E5: INFLATION(ESSENTIAL) | F5: INFLATION(HEALTH) | H5: Year | I5: Month | J5: INFLATION(FOOD) | K5: INFLATION(ESSENTIAL) | L5: INFLATION(HEALTH) | N5: Year | O5: Month | P5: INFLATION(FOOD) | Q5: INFLATION(ESSENTIAL) | R5: INFLATION(HEALTH)
B6: 2018 | C6: March | D6: -0.24994319 | E6: 0.36809816 | F6: 0.37369208 | H6: 2020 | I6: April | J6: 3.4953044 | K6: -0.95415537 | L6: -1.0505581 | N6: 2020 | O6: March | P6: -0.84745763 | Q6: 0.13568521 | R6: 0.39551747
B7: 2018 | C7: April | D7: 0.062642369 | E7: 0.64792176 | F7: 0.67014147 | H7: 2020 | I7: May | J7: 15.495884 | K7: 0.49307416 | L7: 1.2276045
B8: 2018 | C8: May | D8: 0.15366228 | E8: 0.47370339 | F8: 0.59171598 | H8: 2020 | I8: June | J8: -13.189517 | K8: 0.49065487 | L8: 1.2127171
B9: 2018 | C9: June | D9: 0.81259234 | E9: 0.36266925 | F9: 0.14705882 | H9: 2020 | I9: July | J9: 0 | K9: 0 | L9: 0
B10: 2018 | C10: July | D10: 1.1949721 | E10: 0.67453626 | F10: 0.58737151 | H10: 2020 | I10: August | J10: 1.4439699 | K10: 1.1063445 | L10: 0.38860104
B11: 2018 | C11: August | D11: 0.18938339 | E11: 0.65805217 | F11: 0.51094891 | H11: 2020 | I11: September | J11: 0.59141941 | K11: 0.15631979 | L11: 0.38709677
B12: 2018 | C12: September | D12: -1.0674376 | E12: 0.55865922 | F12: 0.50835149 | H12: 2020 | I12: October | J12: 2.0727454 | K12: 0.30100334 | L12: 0.44987147
B13: 2018 | C13: October | D13: -0.18544535 | E13: 1.0047281 | F13: 2.6734104 | H13: 2020 | I13: November | J13: 2.2942497 | K13: 0.32232967 | L13: 0.57581574
B14: 2018 | C14: November | D14: -0.028149983 | E14: -0.03510825 | F14: 0 | H14: 2020 | I14: December | J14: 0.64420691 | K14: 0.42100598 | L14: 0.69974555
B15: 2018 | C15: December | D15: -0.72647407 | E15: -0.15218918 | F15: 1.9704433 | H15: 2021 | I15: March | J15: -3.3047271 | K15: 2.537511 | L15: 2.1478206
B16: 2019 | C16: January | D16: -0.53324257 | E16: -0.25794349 | F16: 0.13802622 | H16: 2021 | I16: April | J16: 1.2111405 | K16: 0.38734668 | L16: 0.37105751
B17: 2019 | C17: February | D17: 0.21101859 | E17: 0.070530152 | F17: 0.34458994 | H17: 2021 | I17: May | J17: 2.0154062 | K17: 1.414791 | L17: 2.1565003
B18: 2019 | C18: March | D18: 0.33008935 | E18: 0.32890873 | F18: 0.41208791 | H18: 2021 | I18: June | J18: 1.3392221 | K18: 0.2113718 | L18: 0.30156815
... B28: 2020 | C28: February | D28: -1.4842301 | E28: 0.39732092 | F28: 0.33068783 | H28: 2022 | I28: April | J28: 4.3494186 | K28: 6.4222963 | L28: 6.5895954
G31: MARCH 2020
B56: INSIGHTS
B57: Inflation on food items increases more after march 2020 as COVID pandemic affects food category the most as the inflation rate on food items was less before march 2020.
B58: Inflation on essential items and healthcare system was less after march 2020 as due to pandemic the price of healthcare and essential items as government was giving subsidies to all its citizens
B59: After may 2020 the inflation rate instantly decreases and became lowest in june 2020 and after that start increasing gradually
B60: Before march 2020, the maximun inflation was for the healthcare sector in the month of october 2018.
B61: Before march 2020, the inflation rate on essentials was moderate neither too high nor low
B62: After march 2020 both the sectors was having slight changes.

Sheet Problem 4
A1: Sector | B1: Year | C1: Month | D1: Cereals and products | E1: Meat and fish | F1: Egg | G1: Milk and products | H1: Oils and fats | I1: Fruits | J1: Vegetables | K1: Pulses and products | L1: Sugar and Confectionery | M1: Spices | N1: Non-alcoholic beverages | O1: Prepared meals, snacks, sweets etc. | P1: Food and beverages | Q1: FOOD | R1: Clothing and footwear | S1: Housing | T1: Fuel and light | U1: Household goods and services | V1: Transport and communication | W1: Education | X1: ESSENTIAL SERVICES | Y1: HEALTH
A2: Rural+Urban | B2: 2018 | C2: March | D2: 136.2 | E2: 143.6 | F2: 138.3 | G2: 141.2 | H2: 120.7 | I2: 146.2 | J2: 134.6 | K2: 124.6 | L2: 116.1 | M2: 137.8 | N2: 129.1 | O2: 150.4 | P2: 137.2 | Q2: =SUM($D2:$P2) -> 1756 | R2: 143.1 | S2: 142 | T2: 136.5 | U2: 135.6 | V2: 121 | W2: 139.8 | X2: =SUM($R2:$W2) -> 818 | Y2: 134.3
A3: Rural+Urban | B3: 2018 | C3: April | D3: 136.4 | E3: 144.4 | F3: 133.9 | G3: 141.6 | H3: 121 | I3: 153.5 | J3: 132.6 | K3: 123.5 | L3: 113.7 | M3: 138.2 | N3: 129.6 | O3: 151.2 | P3: 137.5 | Q3: 1757.1 | R3: 144 | S3: 142.9 | T3: 136.5 | U3: 136.6 | V3: 121.9 | W3: 141.4 | X3: 823.3 | Y3: 135.2
A4: Rural+Urban | B4: 2018 | C4: May | D4: 136.6 | E4: 146.6 | F4: 133.6 | G4: 142.1 | H4: 121 | I4: 154.6 | J4: 135.6 | K4: 122.3 | L4: 109.6 | M4: 138.1 | N4: 129.9 | O4: 151.7 | P4: 138.1 | Q4: 1759.8 | R4: 144.7 | S4: 143.2 | T4: 136.9 | U4: 137.4 | V4: 122.9 | W4: 142.1 | X4: 827.2 | Y4: 136
A5: Rural+Urban | B5: 2018 | C5: June | D5: 136.9 | E5: 148.7 | F5: 135.6 | G5: 142.3 | H5: 121.3 | I5: 153.2 | J5: 143.7 | K5: 121.4 | L5: 111.1 | M5: 138.4 | N5: 130.3 | O5: 151.8 | P5: 139.4 | Q5: 1774.1 | R5: 145.2 | S5: 142.5 | T5: 138.1 | U5: 137.9 | V5: 123.7 | W5: 142.8 | X5: 830.2 | Y5: 136.2
A6: Rural+Urban | B6: 2018 | C6: July | D6: 137.5 | E6: 149.1 | F6: 139.2 | G6: 142.5 | H6: 121.4 | I6: 151.6 | J6: 155.9 | K6: 121.7 | L6: 113.5 | M6: 138.9 | N6: 130.3 | O6: 152.3 | P6: 141.4 | Q6: 1795.3 | R6: 145.6 | S6: 143.6 | T6: 139.7 | U6: 138.6 | V6: 123.6 | W6: 144.7 | X6: 835.8 | Y6: 137
A7: Rural+Urban | B7: 2018 | C7: August | D7: 138.3 | E7: 148 | F7: 138.1 | G7: 142.6 | H7: 122.2 | I7: 150.6 | J7: 156.6 | K7: 122.4 | L7: 114.7 | M7: 139.4 | N7: 131.1 | O7: 153 | P7: 141.7 | Q7: 1798.7 | R7: 146.1 | S7: 144.6 | T7: 140.9 | U7: 139.4 | V7: 124.3 | W7: 146 | X7: 841.3 | Y7: 137.7
A8: Rural+Urban | B8: 2018 | C8: September | D8: 138.6 | E8: 145.8 | F8: 135.1 | G8: 142.9 | H8: 122.1 | I8: 145.4 | J8: 150 | K8: 121.4 | L8: 113.7 | M8: 139.5 | N8: 130.8 | O8: 153.8 | P8: 140.4 | Q8: 1779.5 | R8: 146.5 | S8: 145.3 | T8: 142.3 | U8: 139.7 | V8: 126 | W8: 146.2 | X8: 846 | Y8: 138.4
A9: Rural+Urban | B9: 2018 | C9: October | D9: 137.4 | E9: 149.5 | F9: 137.3 | G9: 141.9 | H9: 121.1 | I9: 142.5 | J9: 146.7 | K9: 119.1 | L9: 111.9 | M9: 141 | N9: 133.6 | O9: 154.5 | P9: 139.7 | Q9: 1776.2 | R9: 146.8 | S9: 146.9 | T9: 145.3 | U9: 142.2 | V9: 125.5 | W9: 147.8 | X9: 854.5 | Y9: 142.1
A10: Rural+Urban | B10: 2018 | C10: November | D10: 137.4 | E10: 149.2 | F10: 137.1 | G10: 141.8 | H10: 121.1 | I10: 142.8 | J10: 146.7 | K10: 119.1 | L10: 111.9 | M10: 140.9 | N10: 133.5 | O10: 154.5 | P10: 139.7 | Q10: 1775.7 | R10: 146.7 | S10: 146.9 | T10: 145.1 | U10: 142.2 | V10: 125.5 | W10: 147.8 | X10: 854.2 | Y10: 142.1
A11: Rural+Urban | B11: 2018 | C11: December | D11: 137.5 | E11: 150.5 | F11: 138.8 | G11: 142.1 | H11: 122 | I11: 139.4 | J11: 135.2 | K11: 119.8 | L11: 110.3 | M11: 140.6 | N11: 133.8 | O11: 154.6 | P11: 138.2 | Q11: 1762.8 | R11: 146.8 | S11: 146.5 | T11: 142.7 | U11: 143.2 | V11: 123.6 | W11: 150.1 | X11: 852.9 | Y11: 144.9
A12: Rural+Urban | B12: 2019 | C12: January | D12: 137.1 | E12: 151.4 | F12: 140.2 | G12: 142.1 | H12: 121.8 | I12: 135.4 | J12: 131.3 | K12: 120.3 | L12: 109.1 | M12: 139.4 | N12: 133.3 | O12: 154.6 | P12: 137.4 | Q12: 1753.4 | R12: 146.4 | S12: 147.7 | T12: 139.5 | U12: 143.6 | V12: 123.3 | W12: 150.2 | X12: 850.7 | Y12: 145.1
A13: Rural+Urban | B13: 2019 | C13: February | D13: 137.6 | E13: 152 | F13: 141.5 | G13: 142.2 | H13: 122 | I13: 136.4 | J13: 129.7 | K13: 121 | L13: 109 | M13: 139.7 | N13: 133.6 | O13: 154.9 | P13: 137.5 | Q13: 1757.1 | R13: 146.5 | S13: 148.5 | T13: 138.4 | U13: 143.7 | V13: 123.9 | W13: 150.3 | X13: 851.3 | Y13: 145.6
A14: Rural+Urban | B14: 2019 | C14: March | D14: 137.8 | E14: 153 | F14: 140.3 | G14: 142.3 | H14: 122 | I14: 137.6 | J14: 132.6 | K14: 121.8 | L14: 109 | M14: 139.5 | N14: 133.7 | O14: 155.2 | P14: 138.1 | Q14: 1762.9 | R14: 146.7 | S14: 149 | T14: 139.7 | U14: 143.8 | V14: 124.6 | W14: 150.3 | X14: 854.1 | Y14: 146.2
... A24: Rural+Urban | B24: 2020 | C24: February | D24: 144.8 | E24: 167.5 | F24: 151.8 | G24: 150.8 | H24: 131.4 | I24: 141.8 | J24: 170.7 | K24: 141.1 | L24: 113.6 | M24: 152 | N24: 136.5 | O24: 159.1 | P24: 150.5 | Q24: 1911.6 | R24: 149.5 | S24: 154.8 | T24: 147.2 | U24: 146.4 | V24: 130.3 | W24: 156.2 | X24: 884.4 | Y24: 151.7
B28: after Mar 2020
A29: Sector | B29: Year | C29: Month | D29: Cereals and products | E29: Meat and fish | F29: Egg | G29: Milk and products | H29: Oils and fats | I29: Fruits | J29: Vegetables | K29: Pulses and products | L29: Sugar and Confectionery | M29: Spices | N29: Non-alcoholic beverages | O29: Prepared meals, snacks, sweets etc. | P29: Food and beverages | Q29: FOOD | R29: Clothing and footwear | S29: Housing | T29: Fuel and light | U29: Household goods and services | V29: Transport and communication | W29: Education | X29: ESSENTIAL SERVICES | Y29: HEALTH
A30: Rural+Urban | B30: 2020 | C30: March | D30: 145.1 | E30: 167 | F30: 148.1 | G30: 151.5 | H30: 131.2 | I30: 142.5 | J30: 157.3 | K30: 141.1 | L30: 113.2 | M30: 153.2 | N30: 136.7 | O30: 159.6 | P30: 148.9 | Q30: =SUM(D30:P30) -> 1895.4 | R30: 149.8 | S30: 154.5 | T30: 148.9 | U30: 146.4 | V30: 129.9 | W30: 156.1 | X30: =SUM(R30:W30) -> 885.6 | Y30: 152.3
A31: Rural+Urban | B31: 2020 | C31: April | D31: 148.7 | E31: 178.55 | F31: 148.8 | G31: 155.6 | H31: 135.1 | I31: 149.9 | J31: 168.6 | K31: 150.4 | L31: 120.3 | M31: 157.1 | N31: 136.8 | O31: 160.4 | P31: 151.4 | Q31: =SUM(D31:P31) -> 1961.65 | R31: 146.4 | S31: 155.6 | T31: 144.1 | U31: 151.6 | V31: 126.95 | W31: 152.5 | X31: =SUM(R31:W31) -> 877.15 | Y31: 150.7
A32: Rural+Urban | B32: 2020 | C32: May | D32: 149.15 | E32: 185.625 | F32: 451.5 | G32: 154.45 | H32: 135.7 | I32: 148.55 | J32: 162.55 | K32: 150.65 | L32: 117.25 | M32: 158.3 | N32: 138.1 | O32: 161.1 | P32: 152.7 | Q32: =SUM(D32:P32) -> 2265.625 | R32: 148.9 | S32: 155.15 | T32: 143 | U32: 149 | V32: 130.975 | W32: 154.45 | X32: =SUM(R32:W32) -> 881.475 | Y32: 152.55
A33: Rural+Urban | B33: 2020 | C33: June | D33: 149.6 | E33: 192.7 | F33: 151.4 | G33: 153.3 | H33: 136.3 | I33: 147.2 | J33: 156.5 | K33: 150.9 | L33: 114.2 | M33: 159.5 | N33: 139.4 | O33: 161.8 | P33: 154 | Q33: =SUM(D33:P33) -> 1966.8 | R33: 151.4 | S33: 154.7 | T33: 141.9 | U33: 146.4 | V33: 135 | W33: 156.4 | X33: =SUM(R33:W33) -> 885.8 | Y33: 154.4
A34: Rural+Urban | B34: 2020 | C34: July | D34: 149.6 | E34: 192.7 | F34: 151.4 | G34: 153.3 | H34: 136.3 | I34: 147.2 | J34: 156.5 | K34: 150.9 | L34: 114.2 | M34: 159.5 | N34: 139.4 | O34: 161.8 | P34: 154 | Q34: =SUM(D34:P34) -> 1966.8 | R34: 151.4 | S34: 154.7 | T34: 141.9 | U34: 146.4 | V34: 135 | W34: 156.4 | X34: =SUM(R34:W34) -> 885.8 | Y34: 154.4
